import pytest
import sys
import os
import threading
from unittest.mock import patch, MagicMock

sys.path.insert(0, '..')
import Snatch

def test_background_init_bug():
    """Test for the bug in _run_background_init function."""
    if hasattr(Snatch, '_run_background_init'):
        # Create a mock config object
        mock_config = MagicMock()
        
        # Test the function in isolation
        with patch.object(threading.Thread, 'start'), \
             patch.object(threading.Thread, 'join'):
            try:
                # Call the function with a mock config
                Snatch._run_background_init(mock_config)
                # If we get here without an exception, the bug might be fixed or needs different conditions
                assert True
            except UnboundLocalError as e:
                # This is the bug we observed
                assert "cannot access local variable 'any_updates_found'" in str(e)
    else:
        pytest.skip("_run_background_init function not found")